<sdf version='1.7'>
  <model name='solo'>
    <link name='base_link'>
      <inertial>
        <pose>-0.00083 1e-06 -0.000602 0 -0 0</pose>
        <mass>1.25124</mass>
        <inertia>
          <ixx>0.0026622</ixx>
          <ixy>-3.684e-05</ixy>
          <ixz>-1.716e-05</ixz>
          <iyy>0.0138851</iyy>
          <iyz>-9e-08</iyz>
          <izz>0.0160537</izz>
        </inertia>
      </inertial>
      <collision name='base_link_collision'>
        <pose>0 0 0 0 -0 0</pose>
        <geometry>
          <mesh>
            <scale>1 1 1</scale>
            <uri>file:///home/pratik/sdp_ws/src/install/solo12_description/share/solo12_description/meshes/collision/base.stl</uri>
          </mesh>
        </geometry>
      </collision>
      <visual name='base_link_visual'>
        <pose>0 0 0 0 -0 0</pose>
        <geometry>
          <mesh>
            <scale>1 1 1</scale>
            <uri>file:///home/pratik/sdp_ws/src/install/solo12_description/share/solo12_description/meshes/collision/base.stl</uri>
          </mesh>
        </geometry>
      </visual>
    </link>
    <joint name='FL_HAA' type='revolute'>
      <pose relative_to='base_link'>0.2141 0.0875 0 0 -0 0</pose>
      <parent>base_link</parent>
      <child>FL_SHOULDER</child>
      <axis>
        <xyz>1 0 0</xyz>
        <limit>
          <lower>-10</lower>
          <upper>10</upper>
          <effort>1000</effort>
          <velocity>1000</velocity>
        </limit>
        <dynamics>
          <damping>0</damping>
          <friction>0</friction>
          <spring_reference>0</spring_reference>
          <spring_stiffness>0</spring_stiffness>
        </dynamics>
      </axis>
    </joint>
    <link name='FL_SHOULDER'>
      <pose relative_to='FL_HAA'>0 0 0 0 -0 0</pose>
      <inertial>
        <pose>-0.094073 -0.004389 1.4e-05 0 -0 0</pose>
        <mass>0.14196</mass>
        <inertia>
          <ixx>2.802e-05</ixx>
          <ixy>3.687e-05</ixy>
          <ixz>-9e-08</ixz>
          <iyy>0.00038264</iyy>
          <iyz>0</iyz>
          <izz>0.0003805</izz>
        </inertia>
      </inertial>
      <collision name='FL_SHOULDER_collision'>
        <pose>0.0195 0 0 0 -0 0</pose>
        <geometry>
          <mesh>
            <scale>1 1 1</scale>
            <uri>file:///home/pratik/sdp_ws/src/install/solo12_description/share/solo12_description/meshes/collision/hip_fe_fl.stl</uri>
          </mesh>
        </geometry>
      </collision>
      <visual name='FL_SHOULDER_visual'>
        <pose>0.0195 0 0 0 -0 0</pose>
        <geometry>
          <mesh>
            <scale>1 1 1</scale>
            <uri>file:///home/pratik/sdp_ws/src/install/solo12_description/share/solo12_description/meshes/collision/hip_fe_fl.stl</uri>
          </mesh>
        </geometry>
      </visual>
    </link>
    <joint name='FL_HFE' type='revolute'>
      <pose relative_to='FL_SHOULDER'>-0.0195 0.014 0 0 -0 0</pose>
      <parent>FL_SHOULDER</parent>
      <child>FL_UPPER_LEG</child>
      <axis>
        <xyz>0 1 0</xyz>
        <limit>
          <lower>-10</lower>
          <upper>10</upper>
          <effort>1000</effort>
          <velocity>1000</velocity>
        </limit>
        <dynamics>
          <damping>0</damping>
          <friction>0</friction>
          <spring_reference>0</spring_reference>
          <spring_stiffness>0</spring_stiffness>
        </dynamics>
      </axis>
    </joint>
    <link name='FL_UPPER_LEG'>
      <pose relative_to='FL_HFE'>0 0 0 0 -0 0</pose>
      <inertial>
        <pose>1.5e-05 0.017676 -0.078382 0 -0 0</pose>
        <mass>0.147373</mass>
        <inertia>
          <ixx>0.0004154</ixx>
          <ixy>0</ixy>
          <ixz>1e-07</ixz>
          <iyy>0.00041637</iyy>
          <iyz>-4.589e-05</iyz>
          <izz>2.982e-05</izz>
        </inertia>
      </inertial>
      <collision name='FL_UPPER_LEG_collision'>
        <pose>0 0 0 0 -0 0</pose>
        <geometry>
          <mesh>
            <scale>1 1 1</scale>
            <uri>file:///home/pratik/sdp_ws/src/install/solo12_description/share/solo12_description/meshes/collision/isolated_upper_leg_left_side.stl</uri>
          </mesh>
        </geometry>
      </collision>
      <visual name='FL_UPPER_LEG_visual'>
        <pose>0 0 0 0 -0 0</pose>
        <geometry>
          <mesh>
            <scale>1 1 1</scale>
            <uri>file:///home/pratik/sdp_ws/src/install/solo12_description/share/solo12_description/meshes/collision/isolated_upper_leg_left_side.stl</uri>
          </mesh>
        </geometry>
      </visual>
    </link>
    <joint name='FL_KFE' type='revolute'>
      <pose relative_to='FL_UPPER_LEG'>0 0.03745 -0.16 0 -0 0</pose>
      <parent>FL_UPPER_LEG</parent>
      <child>FL_LOWER_LEG</child>
      <axis>
        <xyz>0 1 0</xyz>
        <limit>
          <lower>-10</lower>
          <upper>10</upper>
          <effort>1000</effort>
          <velocity>1000</velocity>
        </limit>
        <dynamics>
          <damping>0</damping>
          <friction>0</friction>
          <spring_reference>0</spring_reference>
          <spring_stiffness>0</spring_stiffness>
        </dynamics>
      </axis>
    </joint>
    <link name='FL_LOWER_LEG'>
      <pose relative_to='FL_KFE'>0 0 0 0 -0 0</pose>
      <inertial>
        <pose>0 0.008139 -0.097149 0 -0 0</pose>
        <mass>0.0331829</mass>
        <inertia>
          <ixx>0.00214163</ixx>
          <ixy>0</ixy>
          <ixz>0</ixz>
          <iyy>0.00214234</iyy>
          <iyz>-1.22515e-06</iyz>
          <izz>0.0020014</izz>
        </inertia>
      </inertial>
      <collision name='FL_LOWER_LEG_collision'>
        <pose>0 0 0 0 -0 0</pose>
        <geometry>
          <mesh>
            <scale>1 1 1</scale>
            <uri>file:///home/pratik/sdp_ws/src/install/solo12_description/share/solo12_description/meshes/collision/isolated_lower_leg_v2_left_side.stl</uri>
          </mesh>
        </geometry>
      </collision>
      <visual name='FL_LOWER_LEG_visual'>
        <pose>0 0 0 0 -0 0</pose>
        <geometry>
          <mesh>
            <scale>1 1 1</scale>
            <uri>file:///home/pratik/sdp_ws/src/install/solo12_description/share/solo12_description/meshes/collision/isolated_lower_leg_v2_left_side.stl</uri>
          </mesh>
        </geometry>
      </visual>
    </link>
    <joint name='FR_HAA' type='revolute'>
      <pose relative_to='base_link'>0.2141 -0.0875 0 0 -0 0</pose>
      <parent>base_link</parent>
      <child>FR_SHOULDER</child>
      <axis>
        <xyz>1 0 0</xyz>
        <limit>
          <lower>-10</lower>
          <upper>10</upper>
          <effort>1000</effort>
          <velocity>1000</velocity>
        </limit>
        <dynamics>
          <damping>0</damping>
          <friction>0</friction>
          <spring_reference>0</spring_reference>
          <spring_stiffness>0</spring_stiffness>
        </dynamics>
      </axis>
    </joint>
    <link name='FR_SHOULDER'>
      <pose relative_to='FR_HAA'>0 0 0 0 -0 0</pose>
      <inertial>
        <pose>-0.094073 0.004389 -1.4e-05 0 -0 0</pose>
        <mass>0.14196</mass>
        <inertia>
          <ixx>2.802e-05</ixx>
          <ixy>-3.687e-05</ixy>
          <ixz>9e-08</ixz>
          <iyy>0.00038264</iyy>
          <iyz>0</iyz>
          <izz>0.0003805</izz>
        </inertia>
      </inertial>
      <collision name='FR_SHOULDER_collision'>
        <pose>0.0195 0 0 0 -0 0</pose>
        <geometry>
          <mesh>
            <scale>1 1 1</scale>
            <uri>file:///home/pratik/sdp_ws/src/install/solo12_description/share/solo12_description/meshes/collision/hip_fe_fr.stl</uri>
          </mesh>
        </geometry>
      </collision>
      <visual name='FR_SHOULDER_visual'>
        <pose>0.0195 0 0 0 -0 0</pose>
        <geometry>
          <mesh>
            <scale>1 1 1</scale>
            <uri>file:///home/pratik/sdp_ws/src/install/solo12_description/share/solo12_description/meshes/collision/hip_fe_fr.stl</uri>
          </mesh>
        </geometry>
      </visual>
    </link>
    <joint name='FR_HFE' type='revolute'>
      <pose relative_to='FR_SHOULDER'>-0.0195 -0.014 0 0 -0 0</pose>
      <parent>FR_SHOULDER</parent>
      <child>FR_UPPER_LEG</child>
      <axis>
        <xyz>0 1 0</xyz>
        <limit>
          <lower>-10</lower>
          <upper>10</upper>
          <effort>1000</effort>
          <velocity>1000</velocity>
        </limit>
        <dynamics>
          <damping>0</damping>
          <friction>0</friction>
          <spring_reference>0</spring_reference>
          <spring_stiffness>0</spring_stiffness>
        </dynamics>
      </axis>
    </joint>
    <link name='FR_UPPER_LEG'>
      <pose relative_to='FR_HFE'>0 0 0 0 -0 0</pose>
      <inertial>
        <pose>-1.5e-05 -0.017676 -0.078382 0 -0 0</pose>
        <mass>0.147373</mass>
        <inertia>
          <ixx>0.0004154</ixx>
          <ixy>0</ixy>
          <ixz>-1e-07</ixz>
          <iyy>0.00041637</iyy>
          <iyz>4.589e-05</iyz>
          <izz>2.982e-05</izz>
        </inertia>
      </inertial>
      <collision name='FR_UPPER_LEG_collision'>
        <pose>0 0 0 0 -0 0</pose>
        <geometry>
          <mesh>
            <scale>1 1 1</scale>
            <uri>file:///home/pratik/sdp_ws/src/install/solo12_description/share/solo12_description/meshes/collision/isolated_upper_leg_right_side.stl</uri>
          </mesh>
        </geometry>
      </collision>
      <visual name='FR_UPPER_LEG_visual'>
        <pose>0 0 0 0 -0 0</pose>
        <geometry>
          <mesh>
            <scale>1 1 1</scale>
            <uri>file:///home/pratik/sdp_ws/src/install/solo12_description/share/solo12_description/meshes/collision/isolated_upper_leg_right_side.stl</uri>
          </mesh>
        </geometry>
      </visual>
    </link>
    <joint name='FR_KFE' type='revolute'>
      <pose relative_to='FR_UPPER_LEG'>0 -0.03745 -0.16 0 -0 0</pose>
      <parent>FR_UPPER_LEG</parent>
      <child>FR_LOWER_LEG</child>
      <axis>
        <xyz>0 1 0</xyz>
        <limit>
          <lower>-10</lower>
          <upper>10</upper>
          <effort>1000</effort>
          <velocity>1000</velocity>
        </limit>
        <dynamics>
          <damping>0</damping>
          <friction>0</friction>
          <spring_reference>0</spring_reference>
          <spring_stiffness>0</spring_stiffness>
        </dynamics>
      </axis>
    </joint>
    <link name='FR_LOWER_LEG'>
      <pose relative_to='FR_KFE'>0 0 0 0 -0 0</pose>
      <inertial>
        <pose>0 -0.008139 -0.097149 0 -0 0</pose>
        <mass>0.0331829</mass>
        <inertia>
          <ixx>0.00214163</ixx>
          <ixy>0</ixy>
          <ixz>0</ixz>
          <iyy>0.00214234</iyy>
          <iyz>1.22515e-06</iyz>
          <izz>0.0020014</izz>
        </inertia>
      </inertial>
      <collision name='FR_LOWER_LEG_collision'>
        <pose>0 0 0 0 -0 0</pose>
        <geometry>
          <mesh>
            <scale>1 1 1</scale>
            <uri>file:///home/pratik/sdp_ws/src/install/solo12_description/share/solo12_description/meshes/collision/isolated_lower_leg_v2_right_side.stl</uri>
          </mesh>
        </geometry>
      </collision>
      <visual name='FR_LOWER_LEG_visual'>
        <pose>0 0 0 0 -0 0</pose>
        <geometry>
          <mesh>
            <scale>1 1 1</scale>
            <uri>file:///home/pratik/sdp_ws/src/install/solo12_description/share/solo12_description/meshes/collision/isolated_lower_leg_v2_right_side.stl</uri>
          </mesh>
        </geometry>
      </visual>
    </link>
    <joint name='HL_HAA' type='revolute'>
      <pose relative_to='base_link'>-0.2141 0.0875 0 0 -0 0</pose>
      <parent>base_link</parent>
      <child>HL_SHOULDER</child>
      <axis>
        <xyz>1 0 0</xyz>
        <limit>
          <lower>-10</lower>
          <upper>10</upper>
          <effort>1000</effort>
          <velocity>1000</velocity>
        </limit>
        <dynamics>
          <damping>0</damping>
          <friction>0</friction>
          <spring_reference>0</spring_reference>
          <spring_stiffness>0</spring_stiffness>
        </dynamics>
      </axis>
    </joint>
    <link name='HL_SHOULDER'>
      <pose relative_to='HL_HAA'>0 0 0 0 -0 0</pose>
      <inertial>
        <pose>0.094073 -0.004389 -1.4e-05 0 -0 0</pose>
        <mass>0.14196</mass>
        <inertia>
          <ixx>2.802e-05</ixx>
          <ixy>-3.687e-05</ixy>
          <ixz>-9e-08</ixz>
          <iyy>0.00038264</iyy>
          <iyz>0</iyz>
          <izz>0.0003805</izz>
        </inertia>
      </inertial>
      <collision name='HL_SHOULDER_collision'>
        <pose>-0.0195 0 0 0 -0 0</pose>
        <geometry>
          <mesh>
            <scale>1 1 1</scale>
            <uri>file:///home/pratik/sdp_ws/src/install/solo12_description/share/solo12_description/meshes/collision/hip_fe_hl.stl</uri>
          </mesh>
        </geometry>
      </collision>
      <visual name='HL_SHOULDER_visual'>
        <pose>-0.0195 0 0 0 -0 0</pose>
        <geometry>
          <mesh>
            <scale>1 1 1</scale>
            <uri>file:///home/pratik/sdp_ws/src/install/solo12_description/share/solo12_description/meshes/collision/hip_fe_hl.stl</uri>
          </mesh>
        </geometry>
      </visual>
    </link>
    <joint name='HL_HFE' type='revolute'>
      <pose relative_to='HL_SHOULDER'>0.0195 0.014 0 0 -0 0</pose>
      <parent>HL_SHOULDER</parent>
      <child>HL_UPPER_LEG</child>
      <axis>
        <xyz>0 1 0</xyz>
        <limit>
          <lower>-10</lower>
          <upper>10</upper>
          <effort>1000</effort>
          <velocity>1000</velocity>
        </limit>
        <dynamics>
          <damping>0</damping>
          <friction>0</friction>
          <spring_reference>0</spring_reference>
          <spring_stiffness>0</spring_stiffness>
        </dynamics>
      </axis>
    </joint>
    <link name='HL_UPPER_LEG'>
      <pose relative_to='HL_HFE'>0 0 0 0 -0 0</pose>
      <inertial>
        <pose>1.5e-05 0.017676 -0.078382 0 -0 0</pose>
        <mass>0.147373</mass>
        <inertia>
          <ixx>0.0004154</ixx>
          <ixy>0</ixy>
          <ixz>1e-07</ixz>
          <iyy>0.00041637</iyy>
          <iyz>-4.589e-05</iyz>
          <izz>2.982e-05</izz>
        </inertia>
      </inertial>
      <collision name='HL_UPPER_LEG_collision'>
        <pose>0 0 0 0 -0 0</pose>
        <geometry>
          <mesh>
            <scale>1 1 1</scale>
            <uri>file:///home/pratik/sdp_ws/src/install/solo12_description/share/solo12_description/meshes/collision/isolated_upper_leg_left_side.stl</uri>
          </mesh>
        </geometry>
      </collision>
      <visual name='HL_UPPER_LEG_visual'>
        <pose>0 0 0 0 -0 0</pose>
        <geometry>
          <mesh>
            <scale>1 1 1</scale>
            <uri>file:///home/pratik/sdp_ws/src/install/solo12_description/share/solo12_description/meshes/collision/isolated_upper_leg_left_side.stl</uri>
          </mesh>
        </geometry>
      </visual>
    </link>
    <joint name='HL_KFE' type='revolute'>
      <pose relative_to='HL_UPPER_LEG'>0 0.03745 -0.16 0 -0 0</pose>
      <parent>HL_UPPER_LEG</parent>
      <child>HL_LOWER_LEG</child>
      <axis>
        <xyz>0 1 0</xyz>
        <limit>
          <lower>-10</lower>
          <upper>10</upper>
          <effort>1000</effort>
          <velocity>1000</velocity>
        </limit>
        <dynamics>
          <damping>0</damping>
          <friction>0</friction>
          <spring_reference>0</spring_reference>
          <spring_stiffness>0</spring_stiffness>
        </dynamics>
      </axis>
    </joint>
    <link name='HL_LOWER_LEG'>
      <pose relative_to='HL_KFE'>0 0 0 0 -0 0</pose>
      <inertial>
        <pose>0 0.008139 -0.097149 0 -0 0</pose>
        <mass>0.0331829</mass>
        <inertia>
          <ixx>0.00214163</ixx>
          <ixy>0</ixy>
          <ixz>0</ixz>
          <iyy>0.00214234</iyy>
          <iyz>-1.22515e-06</iyz>
          <izz>0.0020014</izz>
        </inertia>
      </inertial>
      <collision name='HL_LOWER_LEG_collision'>
        <pose>0 0 0 0 -0 0</pose>
        <geometry>
          <mesh>
            <scale>1 1 1</scale>
            <uri>file:///home/pratik/sdp_ws/src/install/solo12_description/share/solo12_description/meshes/collision/isolated_lower_leg_v2_left_side.stl</uri>
          </mesh>
        </geometry>
      </collision>
      <visual name='HL_LOWER_LEG_visual'>
        <pose>0 0 0 0 -0 0</pose>
        <geometry>
          <mesh>
            <scale>1 1 1</scale>
            <uri>file:///home/pratik/sdp_ws/src/install/solo12_description/share/solo12_description/meshes/collision/isolated_lower_leg_v2_left_side.stl</uri>
          </mesh>
        </geometry>
      </visual>
    </link>
    <joint name='HR_HAA' type='revolute'>
      <pose relative_to='base_link'>-0.2141 -0.0875 0 0 -0 0</pose>
      <parent>base_link</parent>
      <child>HR_SHOULDER</child>
      <axis>
        <xyz>1 0 0</xyz>
        <limit>
          <lower>-10</lower>
          <upper>10</upper>
          <effort>1000</effort>
          <velocity>1000</velocity>
        </limit>
        <dynamics>
          <damping>0</damping>
          <friction>0</friction>
          <spring_reference>0</spring_reference>
          <spring_stiffness>0</spring_stiffness>
        </dynamics>
      </axis>
    </joint>
    <link name='HR_SHOULDER'>
      <pose relative_to='HR_HAA'>0 0 0 0 -0 0</pose>
      <inertial>
        <pose>0.094073 0.004389 1.4e-05 0 -0 0</pose>
        <mass>0.14196</mass>
        <inertia>
          <ixx>2.802e-05</ixx>
          <ixy>3.687e-05</ixy>
          <ixz>9e-08</ixz>
          <iyy>0.00038264</iyy>
          <iyz>0</iyz>
          <izz>0.0003805</izz>
        </inertia>
      </inertial>
      <collision name='HR_SHOULDER_collision'>
        <pose>-0.0195 0 0 0 -0 0</pose>
        <geometry>
          <mesh>
            <scale>1 1 1</scale>
            <uri>file:///home/pratik/sdp_ws/src/install/solo12_description/share/solo12_description/meshes/collision/hip_fe_hr.stl</uri>
          </mesh>
        </geometry>
      </collision>
      <visual name='HR_SHOULDER_visual'>
        <pose>-0.0195 0 0 0 -0 0</pose>
        <geometry>
          <mesh>
            <scale>1 1 1</scale>
            <uri>file:///home/pratik/sdp_ws/src/install/solo12_description/share/solo12_description/meshes/collision/hip_fe_hr.stl</uri>
          </mesh>
        </geometry>
      </visual>
    </link>
    <joint name='HR_HFE' type='revolute'>
      <pose relative_to='HR_SHOULDER'>0.0195 -0.014 0 0 -0 0</pose>
      <parent>HR_SHOULDER</parent>
      <child>HR_UPPER_LEG</child>
      <axis>
        <xyz>0 1 0</xyz>
        <limit>
          <lower>-10</lower>
          <upper>10</upper>
          <effort>1000</effort>
          <velocity>1000</velocity>
        </limit>
        <dynamics>
          <damping>0</damping>
          <friction>0</friction>
          <spring_reference>0</spring_reference>
          <spring_stiffness>0</spring_stiffness>
        </dynamics>
      </axis>
    </joint>
    <link name='HR_UPPER_LEG'>
      <pose relative_to='HR_HFE'>0 0 0 0 -0 0</pose>
      <inertial>
        <pose>-1.5e-05 -0.017676 -0.078382 0 -0 0</pose>
        <mass>0.147373</mass>
        <inertia>
          <ixx>0.0004154</ixx>
          <ixy>0</ixy>
          <ixz>-1e-07</ixz>
          <iyy>0.00041637</iyy>
          <iyz>4.589e-05</iyz>
          <izz>2.982e-05</izz>
        </inertia>
      </inertial>
      <collision name='HR_UPPER_LEG_collision'>
        <pose>0 0 0 0 -0 0</pose>
        <geometry>
          <mesh>
            <scale>1 1 1</scale>
            <uri>file:///home/pratik/sdp_ws/src/install/solo12_description/share/solo12_description/meshes/collision/isolated_upper_leg_right_side.stl</uri>
          </mesh>
        </geometry>
      </collision>
      <visual name='HR_UPPER_LEG_visual'>
        <pose>0 0 0 0 -0 0</pose>
        <geometry>
          <mesh>
            <scale>1 1 1</scale>
            <uri>file:///home/pratik/sdp_ws/src/install/solo12_description/share/solo12_description/meshes/collision/isolated_upper_leg_right_side.stl</uri>
          </mesh>
        </geometry>
      </visual>
    </link>
    <joint name='HR_KFE' type='revolute'>
      <pose relative_to='HR_UPPER_LEG'>0 -0.03745 -0.16 0 -0 0</pose>
      <parent>HR_UPPER_LEG</parent>
      <child>HR_LOWER_LEG</child>
      <axis>
        <xyz>0 1 0</xyz>
        <limit>
          <lower>-10</lower>
          <upper>10</upper>
          <effort>1000</effort>
          <velocity>1000</velocity>
        </limit>
        <dynamics>
          <damping>0</damping>
          <friction>0</friction>
          <spring_reference>0</spring_reference>
          <spring_stiffness>0</spring_stiffness>
        </dynamics>
      </axis>
    </joint>
    <link name='HR_LOWER_LEG'>
      <pose relative_to='HR_KFE'>0 0 0 0 -0 0</pose>
      <inertial>
        <pose>0 -0.008139 -0.097149 0 -0 0</pose>
        <mass>0.0331829</mass>
        <inertia>
          <ixx>0.00214163</ixx>
          <ixy>0</ixy>
          <ixz>0</ixz>
          <iyy>0.00214234</iyy>
          <iyz>1.22515e-06</iyz>
          <izz>0.0020014</izz>
        </inertia>
      </inertial>
      <collision name='HR_LOWER_LEG_collision'>
        <pose>0 0 0 0 -0 0</pose>
        <geometry>
          <mesh>
            <scale>1 1 1</scale>
            <uri>file:///home/pratik/sdp_ws/src/install/solo12_description/share/solo12_description/meshes/collision/isolated_lower_leg_v2_right_side.stl</uri>
          </mesh>
        </geometry>
      </collision>
      <visual name='HR_LOWER_LEG_visual'>
        <pose>0 0 0 0 -0 0</pose>
        <geometry>
          <mesh>
            <scale>1 1 1</scale>
            <uri>file:///home/pratik/sdp_ws/src/install/solo12_description/share/solo12_description/meshes/collision/isolated_lower_leg_v2_right_side.stl</uri>
          </mesh>
        </geometry>
      </visual>
    </link>
    <frame name='FL_ANKLE' attached_to='FL_LOWER_LEG'>
      <pose>0 0.009 -0.16 0 -0 0</pose>
    </frame>
    <frame name='FL_FOOT' attached_to='FL_ANKLE'/>
    <frame name='FR_ANKLE' attached_to='FR_LOWER_LEG'>
      <pose>0 -0.009 -0.16 0 -0 0</pose>
    </frame>
    <frame name='FR_FOOT' attached_to='FR_ANKLE'/>
    <frame name='HL_ANKLE' attached_to='HL_LOWER_LEG'>
      <pose>0 0.009 -0.16 0 -0 0</pose>
    </frame>
    <frame name='HL_FOOT' attached_to='HL_ANKLE'/>
    <frame name='HR_ANKLE' attached_to='HR_LOWER_LEG'>
      <pose>0 -0.009 -0.16 0 -0 0</pose>
    </frame>
    <frame name='HR_FOOT' attached_to='HR_ANKLE'/>
  </model>
</sdf>
